Workbook

Sheet 가정
A1: 사주 궁합각 (v3) — 수익·마진 모델 [파란색=입력값, 검정=수식]
A3: ① 공통 원가 파라미터
A4: 환율 (₩/USD) | B4: 1350 | F4: 자체 입력(현 시세 근사)
A5: Gemini 2.0 Flash — input ($/1M tok) | B5: 0.1 | F5: 출처: Gemini API Pricing 2026 (aicostcheck)
A6: Gemini 2.0 Flash — output ($/1M tok) | B6: 0.4
A7: Gemini 2.5 Flash — input ($/1M tok) | B7: 0.3
A8: Gemini 2.5 Flash — output ($/1M tok) | B8: 2.5
A9: 재시도/사고토큰 버퍼 배수 | B9: 2 | F9: 실측 전 보수적 2배 가정
A11: ② 액션별 토큰 사용량
B12: input tok | C12: output tok | D12: 모델
A13: 무료궁합 (core) | B13: 2000 | C13: 800 | D13: 2.0F
A14: 심층궁합 (프리미엄) | B14: 3000 | C14: 2500 | D14: 2.5F
A15: 관계코칭 (구독, 월 누적) | B15: 300000 | C15: 45000 | D15: 2.5F | F15: 월 150메시지 가정
A16: 매칭 AI (구독, 월 누적) | B16: 100000 | C16: 20000 | D16: 2.5F
A18: ③ AI 원가(₩) — 자동계산
A19: 무료궁합 1건 | B19: =(B13*B5+C13*B6)/1000000*B4*B9 -> 1.404
A20: 심층궁합 1건 | B20: =(B14*B7+C14*B8)/1000000*B4*B9 -> 19.305
A21: 관계코칭 1인·월 | B21: =(B15*B7+C15*B8)/1000000*B4*B9 -> 546.75
A22: 매칭 AI 1인·월 | B22: =(B16*B7+C16*B8)/1000000*B4*B9 -> 216
A24: ④ 기타 변동비
A25: 결제 수수료율 | B25: 0.032 | F25: 간편결제/PG 소형가맹 보수치 (출처: PortOne/토스)
A26: 휴대폰 본인인증 (건/₩) | B26: 50 | F26: 매칭 가입 시 1회 (출처: NICE/통신사 근사)
A27: 커머스 원가율(COGS) | B27: 0.55 | F27: 실물·제휴 굿즈 블렌디드(디지털 굿즈는 더 낮음)
A29: ⑤ 가격 (₩)
A30: 심층궁합 (단건) | B30: 9900
A31: 관계 구독 (월) | B31: 9900
A32: 매칭 구독 (월, 블렌디드) | B32: 19900 | F32: 남 29,900 / 여 무료·할인 혼합
A33: 커머스 객단가(AOV) | B33: 12000
A35: ⑥ 시나리오 퍼널 (월)
C36: 보수(Base) | D36: 성장(Growth) | E36: 대목(월,Peak)
A37: 신규 방문 / 월 | C37: 40000 | D37: 150000 | E37: 250000
A38: 무료궁합 완료율 | C38: 0.45 | D38: 0.45 | E38: 0.45
A39: 심층궁합 전환율(완료대비) | C39: 0.02 | D39: 0.015 | E39: 0.02
A40: 커머스 구매율(완료대비) | C40: 0.01 | D40: 0.01 | E40: 0.015
A41: 관계구독 활성 수 | C41: 400 | D41: 2000 | E41: 3500
A42: 매칭구독 활성 수 | C42: 0 | D42: 800 | E42: 1200 | F42: 매칭은 여성 유동성 확보 후 개방(보수=미개방)
A43: 매칭 신규/월(인증대상) | C43: 0 | D43: 200 | E43: 400
A45: ⑦ 고정비 (월, ₩)
C46: 보수 | D46: 성장 | E46: 대목
A47: 인프라(서버·DB·Vercel) | C47: 150000 | D47: 700000 | E47: 1500000
...

Sheet 유닛이코노믹스
A1: 상품별 유닛 이코노믹스 (건/월 단위 기여이익)
A3: 상품 | B3: 가격(₩) | C3: AI원가 | D3: 결제수수료 | E3: 기타변동 | F3: 기여이익 | G3: 기여이익률
A4: 심층궁합 (단건) | B4: =가정!B30 -> 9900 | C4: =가정!B20 -> 19.305 | D4: =B4*가정!B25 -> 316.8 | E4: 0 | F4: =B4-C4-D4-E4 -> 9563.895 | G4: =F4/B4 -> 0.96605
A5: 관계구독 (월/인) | B5: =가정!B31 -> 9900 | C5: =가정!B21 -> 546.75 | D5: =B5*가정!B25 -> 316.8 | E5: 0 | F5: =B5-C5-D5-E5 -> 9036.45 | G5: =F5/B5 -> 0.91277273
A6: 매칭구독 (월/인) | B6: =가정!B32 -> 19900 | C6: =가정!B22 -> 216 | D6: =B6*가정!B25 -> 636.8 | E6: 0 | F6: =B6-C6-D6-E6 -> 19047.2 | G6: =F6/B6 -> 0.95714573
A7: 커머스 (주문) | B7: =가정!B33 -> 12000 | C7: 0 | D7: =B7*가정!B25 -> 384 | E7: =B7*가정!B27 -> 6600 | F7: =B7-C7-D7-E7 -> 5016 | G7: =F7/B7 -> 0.418
A8: 무료궁합 (유입원가) | B8: 0 | C8: =가정!B19 -> 1.404 | D8: 0 | E8: 0 | F8: =B8-C8-D8-E8 -> -1.404 | G8: —
A10: 핵심: 디지털 상품이라 기여이익률 90%+ (커머스만 ~42%). 마진이 문제가 아니라 "볼륨(유입·전환)"이 전부.
A11: 본인인증(₩50)은 매칭 최초 가입 1회만 → 월 기여이익에는 미반영, 시나리오 변동비에서 별도 계상.

Sheet 시나리오PL
A1: 월간 손익(P&L) — 시나리오 비교
A3: 항목 | B3: 보수(Base) | C3: 성장(Growth) | D3: 대목(월,Peak)
A4: — 물량 —
A5: 무료궁합 완료수 | B5: =가정!C37*가정!C38 -> 18000 | C5: =가정!D37*가정!D38 -> 67500 | D5: =가정!E37*가정!E38 -> 112500
A6: 심층궁합 건수 | B6: =가정!C37*가정!C38*가정!C39 -> 360 | C6: =가정!D37*가정!D38*가정!D39 -> 1012.5 | D6: =가정!E37*가정!E38*가정!E39 -> 2250
A7: 커머스 주문수 | B7: =가정!C37*가정!C38*가정!C40 -> 180 | C7: =가정!D37*가정!D38*가정!D40 -> 675 | D7: =가정!E37*가정!E38*가정!E40 -> 1687.5
A8: 관계구독 활성 | B8: =가정!C41 -> 400 | C8: =가정!D41 -> 2000 | D8: =가정!E41 -> 3500
A9: 매칭구독 활성 | B9: =가정!C42 -> 0 | C9: =가정!D42 -> 800 | D9: =가정!E42 -> 1200
A11: — 매출 —
A12: 심층궁합 매출 | B12: =B6*가정!B30 -> 3564000 | C12: =C6*가정!B30 -> 10023750 | D12: =D6*가정!B30 -> 22275000
A13: 관계구독 매출 | B13: =B8*가정!B31 -> 3960000 | C13: =C8*가정!B31 -> 19800000 | D13: =D8*가정!B31 -> 34650000
A14: 매칭구독 매출 | B14: =B9*가정!B32 -> 0 | C14: =C9*가정!B32 -> 15920000 | D14: =D9*가정!B32 -> 23880000
A15: 커머스 매출 | B15: =B7*가정!B33 -> 2160000 | C15: =C7*가정!B33 -> 8100000 | D15: =D7*가정!B33 -> 20250000
A16: 총매출 | B16: =SUM(B12:B15) -> 9684000 | C16: =SUM(C12:C15) -> 53843750 | D16: =SUM(D12:D15) -> 101055000
A18: — 변동비 —
A19: AI 원가 | B19: =B5*가정!B19+B6*가정!B20+B8*가정!B21+B9*가정!B22 -> 250921.8 | C19: =C5*가정!B19+C6*가정!B20+C8*가정!B21+C9*가정!B22 -> 1380616.3 | D19: =D5*가정!B19+D6*가정!B20+D8*가정!B21+D9*가정!B22 -> 2374211.2
A20: 결제 수수료 | B20: =B16*가정!B25 -> 309888 | C20: =C16*가정!B25 -> 1723000 | D20: =D16*가정!B25 -> 3233760
A21: 커머스 COGS | B21: =B15*가정!B27 -> 1188000 | C21: =C15*가정!B27 -> 4455000 | D21: =D15*가정!B27 -> 11137500
A22: 본인인증(매칭신규) | B22: =가정!C43*가정!B26 -> 0 | C22: =가정!D43*가정!B26 -> 10000 | D22: =가정!E43*가정!B26 -> 20000
A23: 총변동비 | B23: =SUM(B19:B22) -> 1748809.8 | C23: =SUM(C19:C22) -> 7568616.3 | D23: =SUM(D19:D22) -> 16765471
A25: 매출총이익 | B25: =B16-B23 -> 7935190.2 | C25: =C16-C23 -> 46275134 | D25: =D16-D23 -> 84289529
A26: 매출총이익률 | B26: =B25/B16 -> 0.81941245 | C26: =C25/C16 -> 0.85943371 | D26: =D25/D16 -> 0.83409558
A28: 고정비 합계 | B28: =가정!C51 -> 650000 | C28: =가정!D51 -> 4180000 | D28: =가정!E51 -> 10200000
A30: 영업이익(인건비前) | B30: =B25-B28 -> 7285190.2 | C30: =C25-C28 -> 42095134 | D30: =D25-D28 -> 74089529
A31: 영업이익률 | B31: =B30/B16 -> 0.75229143 | C31: =C30/C16 -> 0.78180167 | D31: =D30/D16 -> 0.73316044
A32: 연환산 영업이익(×12) | B32: =B30*12 -> 87422282 | C32: =C30*12 -> 5.051416e+08 | D32: =D30*12 -> 889074345
A34: 대목은 단발 스파이크(월)라 연환산 무의미 → 보수/성장만 연환산 참고.
A35: 성장·대목은 (a)바이럴 K (b)매칭 여성 유동성이 실현될 때만 성립. 보수는 매칭 없이도 도는 하방.

Sheet 12개월빌드업
A1: 12개월 빌드업 (성장 경로) — 구독 누적·월 손익
N2: 신규 관계구독 전환율(완료대비) | O2: 0.004
A3: 항목 | B3: M1 | C3: M2 | D3: M3 | E3: M4 | F3: M5 | G3: M6 | H3: M7 | I3: M8 | J3: M9 | K3: M10 | L3: M11 | M3: M12 | N3: 구독 월 이탈률(churn) | O3: 0.1
A4: 신규 방문(입력) | B4: 20000 | C4: 30000 | D4: 45000 | E4: 60000 | F4: 75000 | G4: 90000 | H4: 105000 | I4: 115000 | J4: 125000 | K4: 135000 | L4: 145000 | M4: 150000 | N4: 완료율(→가정) | O4: =가정!C38 -> 0.45
A5: 무료궁합 완료수 | B5: =B4*$O$4 -> 9000 | C5: =C4*$O$4 -> 13500 | D5: =D4*$O$4 -> 20250 | E5: =E4*$O$4 -> 27000 | F5: =F4*$O$4 -> 33750 | G5: =G4*$O$4 -> 40500 | H5: =H4*$O$4 -> 47250 | I5: =I4*$O$4 -> 51750 | ... M5: =M4*$O$4 -> 67500 | N5: 심층 전환율(→가정) | O5: =가정!D39 -> 0.015
A6: 심층궁합 건수 | B6: =B5*$O$5 -> 135 | C6: =C5*$O$5 -> 202.5 | D6: =D5*$O$5 -> 303.75 | E6: =E5*$O$5 -> 405 | F6: =F5*$O$5 -> 506.25 | G6: =G5*$O$5 -> 607.5 | H6: =H5*$O$5 -> 708.75 | I6: =I5*$O$5 -> 776.25 | ... M6: =M5*$O$5 -> 1012.5 | N6: 커머스 구매율(→가정) | O6: =가정!D40 -> 0.01
A7: 커머스 주문수 | B7: =B5*$O$6 -> 90 | C7: =C5*$O$6 -> 135 | D7: =D5*$O$6 -> 202.5 | E7: =E5*$O$6 -> 270 | F7: =F5*$O$6 -> 337.5 | G7: =G5*$O$6 -> 405 | H7: =H5*$O$6 -> 472.5 | I7: =I5*$O$6 -> 517.5 | ... M7: =M5*$O$6 -> 675
A8: 신규 관계구독 | B8: =B5*$O$2 -> 36 | C8: =C5*$O$2 -> 54 | D8: =D5*$O$2 -> 81 | E8: =E5*$O$2 -> 108 | F8: =F5*$O$2 -> 135 | G8: =G5*$O$2 -> 162 | H8: =H5*$O$2 -> 189 | I8: =I5*$O$2 -> 207 | ... M8: =M5*$O$2 -> 270
A9: 관계구독 활성 | B9: =B8 -> 36 | C9: =B9*(1-$O$3)+C8 -> 86.4 | D9: =C9*(1-$O$3)+D8 -> 158.76 | E9: =D9*(1-$O$3)+E8 -> 250.884 | F9: =E9*(1-$O$3)+F8 -> 360.7956 | G9: =F9*(1-$O$3)+G8 -> 486.71604 | H9: =G9*(1-$O$3)+H8 -> 627.04444 | I9: =H9*(1-$O$3)+I8 -> 771.33999 | J9: =I9*(1-$O$3)+J8 -> 919.20599 | ... M9: =L9*(1-$O$3)+M8 -> 1371.8312
A10: 신규 매칭구독(입력) | B10: 0 | C10: 0 | D10: 0 | E10: 0 | F10: 80 | G10: 120 | H10: 150 | I10: 180 | J10: 210 | K10: 240 | L10: 270 | M10: 300
A11: 매칭구독 활성 | B11: =B10 -> 0 | C11: =B11*(1-$O$3)+C10 -> 0 | D11: =C11*(1-$O$3)+D10 -> 0 | E11: =D11*(1-$O$3)+E10 -> 0 | F11: =E11*(1-$O$3)+F10 -> 80 | G11: =F11*(1-$O$3)+G10 -> 192 | H11: =G11*(1-$O$3)+H10 -> 322.8 | I11: =H11*(1-$O$3)+I10 -> 470.52 | J11: =I11*(1-$O$3)+J10 -> 633.468 | ... M11: =L11*(1-$O$3)+M10 -> 1199.1982
A12: 총매출 | B12: =B6*가정!B30+B9*가정!B31+B11*가정!B32+B7*가정!B33 -> 2772900 | C12: =C6*가정!B30+C9*가정!B31+C11*가정!B32+C7*가정!B33 -> 4480110 | D12: =D6*가정!B30+D9*가정!B31+D11*가정!B32+D7*가정!B33 -> 7008849 | E12: =E6*가정!B30+E9*가정!B31+E11*가정!B32+E7*가정!B33 -> 9733251.6 | F12: =F6*가정!B30+F9*가정!B31+F11*가정!B32+F7*가정!B33 -> 14225751 | G12: =G6*가정!B30+G9*가정!B31+G11*가정!B32+G7*가정!B33 -> 19513539 | H12: =H6*가정!B30+H9*가정!B31+H11*가정!B32+H7*가정!B33 -> 25318085 | I12: =I6*가정!B30+I9*가정!B31+I11*가정!B32+I7*가정!B33 -> 30894489 | J12: =J6*가정!B30+J9*가정!B31+J11*가정!B32+J7*가정!B33 -> 36809278 | K12: =K6*가정!B30+K9*가정!B31+K11*가정!B32+K7*가정!B33 -> 43028612 | L12: =L6*가정!B30+L9*가정!B31+L11*가정!B32+L7*가정!B33 -> 49522039 | M12: =M6*가정!B30+M9*가정!B31+M11*가정!B32+M7*가정!B33 -> 55568922
A13: 총변동비 | B13: =B5*가정!B19+B6*가정!B20+B9*가정!B21+B11*가정!B22+B12*가정!B25+B7*가정!B33*가정!B27+B10*가정!B26 -> 717657.97 | C13: =C5*가정!B19+C6*가정!B20+C9*가정!B21+C11*가정!B22+C12*가정!B25+C7*가정!B33*가정!B27+C10*가정!B26 -> 1104466 | D13: =D5*가정!B19+D6*가정!B20+D9*가정!B21+D11*가정!B22+D12*가정!B25+D7*가정!B33*가정!B27+D10*가정!B26 -> 1681880.1 | E13: =E5*가정!B19+E6*가정!B20+E9*가정!B21+E11*가정!B22+E12*가정!B25+E7*가정!B33*가정!B27+E10*가정!B26 -> 2276361.4 | F13: =F5*가정!B19+F6*가정!B20+F9*가정!B21+F11*가정!B22+F12*가정!B25+F7*가정!B33*가정!B27+F10*가정!B26 -> 2958427.2 | G13: =G5*가정!B19+G6*가정!B20+G9*가정!B21+G11*가정!B22+G12*가정!B25+G7*가정!B33*가정!B27+G10*가정!B26 -> 3679607 | H13: =H5*가정!B19+H6*가정!B20+H9*가정!B21+H11*가정!B22+H12*가정!B25+H7*가정!B33*가정!B27+H10*가정!B26 -> 4428761.5 | I13: =I5*가정!B19+I6*가정!B20+I9*가정!B21+I11*가정!B22+I12*가정!B25+I7*가정!B33*가정!B27+I10*가정!B26 -> 5024128.6 | J13: =J5*가정!B19+J6*가정!B20+J9*가정!B21+J11*가정!B22+J12*가정!B25+J7*가정!B33*가정!B27+J10*가정!B26 -> 5635565.4 | K13: =K5*가정!B19+K6*가정!B20+K9*가정!B21+K11*가정!B22+K12*가정!B25+K7*가정!B33*가정!B27+K10*가정!B26 -> 6261465 | L13: =L5*가정!B19+L6*가정!B20+L9*가정!B21+L11*가정!B22+L12*가정!B25+L7*가정!B33*가정!B27+L10*가정!B26 -> 6900381 | M13: =M5*가정!B19+M6*가정!B20+M9*가정!B21+M11*가정!B22+M12*가정!B25+M7*가정!B33*가정!B27+M10*가정!B26 -> 7371597.3
A14: 고정비(입력) | B14: 1200000 | C14: 1500000 | D14: 1900000 | E14: 2300000 | F14: 2700000 | G14: 3000000 | H14: 3300000 | I14: 3600000 | J14: 3800000 | K14: 4000000 | L14: 4100000 | M14: 4200000
A15: 영업이익(월) | B15: =B12-B13-B14 -> 855242.03 | C15: =C12-C13-C14 -> 1875644 | D15: =D12-D13-D14 -> 3426968.9 | E15: =E12-E13-E14 -> 5156890.2 | F15: =F12-F13-F14 -> 8567324.2 | G15: =G12-G13-G14 -> 12833932 | H15: =H12-H13-H14 -> 17589323 | I15: =I12-I13-I14 -> 22270360 | ... M15: =M12-M13-M14 -> 43997325
A16: 누적 영업이익 | B16: =B15 -> 855242.03 | C16: =B16+C15 -> 2730886 | D16: =C16+D15 -> 6157855 | E16: =D16+E15 -> 11314745 | F16: =E16+F15 -> 19882069 | G16: =F16+G15 -> 32716001 | H16: =G16+H15 -> 50305325 | I16: =H16+I15 -> 72575685 | J16: =I16+J15 -> 99949397 | ... M16: =L16+M15 -> 2.1523553e+08
A18: 매칭은 M5부터(여성 유동성 확보 가정) 개방. 방문 램프·매칭신규·고정비는 입력(파란색)이라 조정 가능.

Sheet 손익분기_민감도
A1: 손익분기 & 민감도 (보수 시나리오 기준)
A3: ① 손익분기(BEP)
A4: 보수 고정비(월) | B4: =가정!C51 -> 650000
A5: 심층궁합 1건 기여이익 | B5: =유닛이코노믹스!F4 -> 9563.895
A6: 관계구독 1인·월 기여이익 | B6: =유닛이코노믹스!F5 -> 9036.45
A7: BEP — 심층궁합만으로(건/월) | B7: =B4/B5 -> 67.963941
A8: BEP — 관계구독만으로(활성) | B8: =B4/B6 -> 71.930902
A9: 참고: 보수 시 실제 심층 건수 | B9: =시나리오PL!B6 -> 360
A10: 참고: 보수 시 실제 관계구독 활성 | B10: =시나리오PL!B8 -> 400
A11: → 하나만으로도 BEP 초과. 고정비가 낮아 손익분기 문턱이 매우 낮음.
A14: ② 영업이익 민감도 — 심층궁합 전환율
A15: 전환율 → | B15: 0.01 | C15: 0.015 | D15: 0.02 | E15: 0.025 | F15: 0.03
A16: 영업이익(월) | B16: =(가정!C37*가정!C38*B15*가정!B30+가정!C41*가정!B31+가정!C37*가정!C38*가정!C40*가정!B33)-((가정!C37*가정!C38*가정!B19+가정!C37*가정!C38*B15*가정!B20+가정!C41*가정!B21)+(가정!C37*가정!C38*B15*가정!B30+가정!C41*가정!B31+가정!C37*가정!C38*가정!C40*가정!B33)*가정!B25+가정!C37*가정!C38*가정!C40*가정!B33*가정!B27)-가정!C51 -> 5563689.1 | C16: =(가정!C37*가정!C38*C15*가정!B30+가정!C41*가정!B31+가정!C37*가정!C38*가정!C40*가정!B33)-((가정!C37*가정!C38*가정!B19+가정!C37*가정!C38*C15*가정!B20+가정!C41*가정!B21)+(가정!C37*가정!C38*C15*가정!B30+가정!C41*가정!B31+가정!C37*가정!C38*가정!C40*가정!B33)*가정!B25+가정!C37*가정!C38*가정!C40*가정!B33*가정!B27)-가정!C51 -> 6424439.7 | D16: =(가정!C37*가정!C38*D15*가정!B30+가정!C41*가정!B31+가정!C37*가정!C38*가정!C40*가정!B33)-((가정!C37*가정!C38*가정!B19+가정!C37*가정!C38*D15*가정!B20+가정!C41*가정!B21)+(가정!C37*가정!C38*D15*가정!B30+가정!C41*가정!B31+가정!C37*가정!C38*가정!C40*가정!B33)*가정!B25+가정!C37*가정!C38*가정!C40*가정!B33*가정!B27)-가정!C51 -> 7285190.2 | E16: =(가정!C37*가정!C38*E15*가정!B30+가정!C41*가정!B31+가정!C37*가정!C38*가정!C40*가정!B33)-((가정!C37*가정!C38*가정!B19+가정!C37*가정!C38*E15*가정!B20+가정!C41*가정!B21)+(가정!C37*가정!C38*E15*가정!B30+가정!C41*가정!B31+가정!C37*가정!C38*가정!C40*가정!B33)*가정!B25+가정!C37*가정!C38*가정!C40*가정!B33*가정!B27)-가정!C51 -> 8145940.8 | F16: =(가정!C37*가정!C38*F15*가정!B30+가정!C41*가정!B31+가정!C37*가정!C38*가정!C40*가정!B33)-((가정!C37*가정!C38*가정!B19+가정!C37*가정!C38*F15*가정!B20+가정!C41*가정!B21)+(가정!C37*가정!C38*F15*가정!B30+가정!C41*가정!B31+가정!C37*가정!C38*가정!C40*가정!B33)*가정!B25+가정!C37*가정!C38*가정!C40*가정!B33*가정!B27)-가정!C51 -> 9006691.3
A19: ③ 영업이익 민감도 — 관계구독 활성수
A20: 활성수 → | B20: 200 | C20: 400 | D20: 600 | E20: 800 | F20: 1000
A21: 영업이익(월) | B21: =(가정!C37*가정!C38*가정!C39*가정!B30+B20*가정!B31+가정!C37*가정!C38*가정!C40*가정!B33)-((가정!C37*가정!C38*가정!B19+가정!C37*가정!C38*가정!C39*가정!B20+B20*가정!B21)+(가정!C37*가정!C38*가정!C39*가정!B30+B20*가정!B31+가정!C37*가정!C38*가정!C40*가정!B33)*가정!B25+가정!C37*가정!C38*가정!C40*가정!B33*가정!B27)-가정!C51 -> 5477900.2 | C21: =(가정!C37*가정!C38*가정!C39*가정!B30+C20*가정!B31+가정!C37*가정!C38*가정!C40*가정!B33)-((가정!C37*가정!C38*가정!B19+가정!C37*가정!C38*가정!C39*가정!B20+C20*가정!B21)+(가정!C37*가정!C38*가정!C39*가정!B30+C20*가정!B31+가정!C37*가정!C38*가정!C40*가정!B33)*가정!B25+가정!C37*가정!C38*가정!C40*가정!B33*가정!B27)-가정!C51 -> 7285190.2 | D21: =(가정!C37*가정!C38*가정!C39*가정!B30+D20*가정!B31+가정!C37*가정!C38*가정!C40*가정!B33)-((가정!C37*가정!C38*가정!B19+가정!C37*가정!C38*가정!C39*가정!B20+D20*가정!B21)+(가정!C37*가정!C38*가정!C39*가정!B30+D20*가정!B31+가정!C37*가정!C38*가정!C40*가정!B33)*가정!B25+가정!C37*가정!C38*가정!C40*가정!B33*가정!B27)-가정!C51 -> 9092480.2 | E21: =(가정!C37*가정!C38*가정!C39*가정!B30+E20*가정!B31+가정!C37*가정!C38*가정!C40*가정!B33)-((가정!C37*가정!C38*가정!B19+가정!C37*가정!C38*가정!C39*가정!B20+E20*가정!B21)+(가정!C37*가정!C38*가정!C39*가정!B30+E20*가정!B31+가정!C37*가정!C38*가정!C40*가정!B33)*가정!B25+가정!C37*가정!C38*가정!C40*가정!B33*가정!B27)-가정!C51 -> 10899770 | F21: =(가정!C37*가정!C38*가정!C39*가정!B30+F20*가정!B31+가정!C37*가정!C38*가정!C40*가정!B33)-((가정!C37*가정!C38*가정!B19+가정!C37*가정!C38*가정!C39*가정!B20+F20*가정!B21)+(가정!C37*가정!C38*가정!C39*가정!B30+F20*가정!B31+가정!C37*가정!C38*가정!C40*가정!B33)*가정!B25+가정!C37*가정!C38*가정!C40*가정!B33*가정!B27)-가정!C51 -> 12707060
A24: ④ 매칭 개방 시 추가 영업이익(월)
A25: 매칭구독 1인·월 기여이익 | B25: =유닛이코노믹스!F6 -> 19047.2
A26: 매칭 활성 400인 가정 시 +영업이익 | B26: =B25*400 -> 7618880
A27: 매칭 활성 800인 가정 시 +영업이익 | B27: =B25*800 -> 15237760
A28: → 매칭이 붙으면 거의 순증(디지털·저원가). 관건은 이익률이 아니라 여성 유동성.
